<sdf version='1.6'>
  <model name='robot'>
    <link name='base_link'>
      <pose frame=''>0 0 0 0 -0 0</pose>
      <inertial>
        <pose frame=''>0 0 0 0 -0 0</pose>
        <mass>1</mass>
        <inertia>
          <ixx>0.236017</ixx>
          <ixy>0</ixy>
          <ixz>0</ixz>
          <iyy>0.236017</iyy>
          <iyz>0</iyz>
          <izz>0.4624</izz>
        </inertia>
      </inertial>
      <collision name='base_link_collision'>
        <pose frame=''>0 0 0 0 -0 0</pose>
        <geometry>
          <mesh>
            <scale>1 1 1</scale>
            <uri>file:///home/adil/sim_ws/src/six_dof/meshes/base.stl</uri>
          </mesh>
        </geometry>
        <surface>
          <contact>
            <ode/>
          </contact>
          <friction>
            <ode>
              <mu>5</mu>
              <mu2>5</mu2>
            </ode>
          </friction>
        </surface>
      </collision>
      <collision name='base_link_fixed_joint_lump__kinect_link_collision_1'>
        <pose frame=''>-3 0 1.2 0 -0 0</pose>
        <geometry>
          <box>
            <size>0.05 0.2 0.05</size>
          </box>
        </geometry>
        <surface>
          <contact>
            <ode/>
          </contact>
          <friction>
            <ode/>
          </friction>
        </surface>
      </collision>
      <visual name='base_link_visual'>
        <pose frame=''>0 0 0 0 -0 0</pose>
        <geometry>
          <mesh>
            <scale>1 1 1</scale>
            <uri>file:///home/adil/sim_ws/src/six_dof/meshes/base.stl</uri>
          </mesh>
        </geometry>
        <material>
          <script>
            <name>Gazebo/Grey</name>
            <uri>file://media/materials/scripts/gazebo.material</uri>
          </script>
        </material>
      </visual>
      <visual name='base_link_fixed_joint_lump__kinect_link_visual_1'>
        <pose frame=''>-3 0 1.2 0 -0 0</pose>
        <geometry>
          <box>
            <size>0.05 0.2 0.05</size>
          </box>
        </geometry>
        <material>
          <script>
            <uri>__default__</uri>
            <name>__default__</name>
          </script>
        </material>
      </visual>
      <velocity_decay/>
      <gravity>1</gravity>
      <velocity_decay/>
      <sensor name='camera_1' type='depth'>
        <always_on>1</always_on>
        <visualize>1</visualize>
        <update_rate>15</update_rate>
        <camera name='__default__'>
          <horizontal_fov>1.0472</horizontal_fov>
          <image>
            <format>B8G8R8</format>
            <width>640</width>
            <height>480</height>
          </image>
          <depth_camera>
            <output>depths</output>
          </depth_camera>
          <clip>
            <near>0.05</near>
            <far>50</far>
          </clip>
        </camera>
        <plugin name='camera_controller' filename='libgazebo_ros_openni_kinect.so'>
          <baseline>0.1</baseline>
          <alwaysOn>1</alwaysOn>
          <updateRate>10.0</updateRate>
          <cameraName>kinect</cameraName>
          <frameName>camera_link_optical</frameName>
          <imageTopicName>rgb/image_raw</imageTopicName>
          <depthImageTopicName>depth/image_raw</depthImageTopicName>
          <pointCloudTopicName>depth/points</pointCloudTopicName>
          <cameraInfoTopicName>rgb/camera_info</cameraInfoTopicName>
          <depthImageCameraInfoTopicName>depth/camera_info</depthImageCameraInfoTopicName>
          <pointCloudCutoff>0.4</pointCloudCutoff>
          <hackBaseline>0.07</hackBaseline>
          <distortionK1>0.0</distortionK1>
          <distortionK2>0.0</distortionK2>
          <distortionK3>0.0</distortionK3>
          <distortionT1>0.0</distortionT1>
          <distortionT2>0.0</distortionT2>
          <CxPrime>0.0</CxPrime>
          <Cx>0.0</Cx>
          <Cy>0.0</Cy>
          <focalLength>0.0</focalLength>
        </plugin>
        <pose frame=''>-3 0 1.2 0 -0 0</pose>
      </sensor>
    </link>
    <joint name='fixed' type='fixed'>
      <child>base_link</child>
      <parent>world</parent>
    </joint>
    <link name='link1'>
      <pose frame=''>0 0 0.17 0 -0 0</pose>
      <inertial>
        <pose frame=''>0 0.05445 0.205749 0 -0 0</pose>
        <mass>3</mass>
        <inertia>
          <ixx>0.135625</ixx>
          <ixy>-0</ixy>
          <ixz>-0</ixz>
          <iyy>0.135625</iyy>
          <iyz>-0</iyz>
          <izz>0.06</izz>
        </inertia>
      </inertial>
      <collision name='link1_collision'>
        <pose frame=''>0 0 0 0 -0 0</pose>
        <geometry>
          <mesh>
            <scale>1 1 1</scale>
            <uri>file:///home/adil/sim_ws/src/six_dof/meshes/link1.stl</uri>
          </mesh>
        </geometry>
        <surface>
          <contact>
            <ode/>
          </contact>
          <friction>
            <ode>
              <mu>5</mu>
              <mu2>5</mu2>
            </ode>
          </friction>
        </surface>
      </collision>
      <visual name='link1_visual'>
        <pose frame=''>0 0 0 0 -0 0</pose>
        <geometry>
          <mesh>
            <scale>1 1 1</scale>
            <uri>file:///home/adil/sim_ws/src/six_dof/meshes/link1.stl</uri>
          </mesh>
        </geometry>
        <material>
          <script>
            <name>Gazebo/Grey</name>
            <uri>file://media/materials/scripts/gazebo.material</uri>
          </script>
        </material>
      </visual>
      <gravity>1</gravity>
      <velocity_decay/>
    </link>
    <joint name='base_link1_joint' type='revolute'>
      <child>link1</child>
      <parent>base_link</parent>
      <axis>
        <xyz>0 0 1</xyz>
        <limit>
          <lower>-3</lower>
          <upper>3</upper>
          <effort>200</effort>
          <velocity>3</velocity>
        </limit>
        <dynamics>
          <spring_reference>0</spring_reference>
          <spring_stiffness>0</spring_stiffness>
        </dynamics>
        <use_parent_model_frame>1</use_parent_model_frame>
      </axis>
    </joint>
    <link name='link2'>
      <pose frame=''>0.05 0.2 0.67 3.14159 1.57079 3.14159</pose>
      <inertial>
        <pose frame=''>-0.001991 0.465745 0.069578 0 -0 0</pose>
        <mass>4.5</mass>
        <inertia>
          <ixx>0.521484</ixx>
          <ixy>0</ixy>
          <ixz>-0</ixz>
          <iyy>0.0271875</iyy>
          <iyz>0</iyz>
          <izz>0.521484</izz>
        </inertia>
      </inertial>
      <collision name='link2_collision'>
        <pose frame=''>0 0 0 0 -0 0</pose>
        <geometry>
          <mesh>
            <scale>1 1 1</scale>
            <uri>file:///home/adil/sim_ws/src/six_dof/meshes/link2.stl</uri>
          </mesh>
        </geometry>
        <surface>
          <contact>
            <ode/>
          </contact>
          <friction>
            <ode>
              <mu>5</mu>
              <mu2>5</mu2>
            </ode>
          </friction>
        </surface>
      </collision>
      <visual name='link2_visual'>
        <pose frame=''>0 0 0 0 -0 0</pose>
        <geometry>
          <mesh>
            <scale>1 1 1</scale>
            <uri>file:///home/adil/sim_ws/src/six_dof/meshes/link2.stl</uri>
          </mesh>
        </geometry>
        <material>
          <script>
            <name>Gazebo/Grey</name>
            <uri>file://media/materials/scripts/gazebo.material</uri>
          </script>
        </material>
      </visual>
      <gravity>1</gravity>
      <velocity_decay/>
    </link>
    <joint name='link1_link2_joint' type='revolute'>
      <child>link2</child>
      <parent>link1</parent>
      <axis>
        <xyz>1 0 -4e-06</xyz>
        <limit>
          <lower>-3</lower>
          <upper>3</upper>
          <effort>200</effort>
          <velocity>3</velocity>
        </limit>
        <dynamics>
          <spring_reference>0</spring_reference>
          <spring_stiffness>0</spring_stiffness>
        </dynamics>
        <use_parent_model_frame>1</use_parent_model_frame>
      </axis>
    </joint>
    <link name='link3'>
      <pose frame=''>0.05 1.2 0.67 3.14159 1.57079 3.14159</pose>
      <inertial>
        <pose frame=''>-0.102694 0.46387 -0.115298 0 -0 0.095993</pose>
        <mass>8</mass>
        <inertia>
          <ixx>1.22373</ixx>
          <ixy>0</ixy>
          <ixz>-0</ixz>
          <iyy>0.0533333</iyy>
          <iyz>0</iyz>
          <izz>1.22373</izz>
        </inertia>
      </inertial>
      <collision name='link3_collision'>
        <pose frame=''>0 0 0 0 -0 0</pose>
        <geometry>
          <mesh>
            <scale>1 1 1</scale>
            <uri>file:///home/adil/sim_ws/src/six_dof/meshes/link3.stl</uri>
          </mesh>
        </geometry>
        <surface>
          <contact>
            <ode/>
          </contact>
          <friction>
            <ode>
              <mu>5</mu>
              <mu2>5</mu2>
            </ode>
          </friction>
        </surface>
      </collision>
      <visual name='link3_visual'>
        <pose frame=''>0 0 0 0 -0 0</pose>
        <geometry>
          <mesh>
            <scale>1 1 1</scale>
            <uri>file:///home/adil/sim_ws/src/six_dof/meshes/link3.stl</uri>
          </mesh>
        </geometry>
        <material>
          <script>
            <name>Gazebo/Grey</name>
            <uri>file://media/materials/scripts/gazebo.material</uri>
          </script>
        </material>
      </visual>
      <gravity>1</gravity>
      <velocity_decay/>
    </link>
    <joint name='link2_link3_joint' type='revolute'>
      <child>link3</child>
      <parent>link2</parent>
      <axis>
        <xyz>1 0 -4e-06</xyz>
        <limit>
          <lower>-3</lower>
          <upper>3</upper>
          <effort>500</effort>
          <velocity>3</velocity>
        </limit>
        <dynamics>
          <spring_reference>0</spring_reference>
          <spring_stiffness>0</spring_stiffness>
        </dynamics>
        <use_parent_model_frame>1</use_parent_model_frame>
      </axis>
    </joint>
    <link name='link4'>
      <pose frame=''>-0.069999 2.283 0.823 3.14159 1.57079 3.14159</pose>
      <inertial>
        <pose frame=''>0 0.074249 -0.033 0 -0 0</pose>
        <mass>1</mass>
        <inertia>
          <ixx>0.00249633</ixx>
          <ixy>0</ixy>
          <ixz>-0</ixz>
          <iyy>0.00249633</iyy>
          <iyz>-0</iyz>
          <izz>0.00343542</izz>
        </inertia>
      </inertial>
      <collision name='link4_collision'>
        <pose frame=''>0 0 0 0 -0 0</pose>
        <geometry>
          <mesh>
            <scale>1 1 1</scale>
            <uri>file:///home/adil/sim_ws/src/six_dof/meshes/link4_n.stl</uri>
          </mesh>
        </geometry>
        <surface>
          <contact>
            <ode/>
          </contact>
          <friction>
            <ode>
              <mu>5</mu>
              <mu2>5</mu2>
            </ode>
          </friction>
        </surface>
      </collision>
      <visual name='link4_visual'>
        <pose frame=''>0 0 0 0 -0 0</pose>
        <geometry>
          <mesh>
            <scale>1 1 1</scale>
            <uri>file:///home/adil/sim_ws/src/six_dof/meshes/link4_n.stl</uri>
          </mesh>
        </geometry>
        <material>
          <script>
            <name>Gazebo/Grey</name>
            <uri>file://media/materials/scripts/gazebo.material</uri>
          </script>
        </material>
      </visual>
      <gravity>1</gravity>
      <velocity_decay/>
    </link>
    <joint name='link3_link4_joint' type='revolute'>
      <child>link4</child>
      <parent>link3</parent>
      <axis>
        <xyz>1 0 -4e-06</xyz>
        <limit>
          <lower>-3</lower>
          <upper>3</upper>
          <effort>200</effort>
          <velocity>3</velocity>
        </limit>
        <dynamics>
          <spring_reference>0</spring_reference>
          <spring_stiffness>0</spring_stiffness>
        </dynamics>
        <use_parent_model_frame>1</use_parent_model_frame>
      </axis>
    </joint>
    <link name='link5'>
      <pose frame=''>-0.069999 2.413 0.823 1.57079 -7e-06 -3.14159</pose>
      <inertial>
        <pose frame=''>0 0.074249 -0.033 0 -0 0</pose>
        <mass>1</mass>
        <inertia>
          <ixx>0.00249633</ixx>
          <ixy>0</ixy>
          <ixz>-0</ixz>
          <iyy>0.00249633</iyy>
          <iyz>-0</iyz>
          <izz>0.00343542</izz>
        </inertia>
      </inertial>
      <collision name='link5_collision'>
        <pose frame=''>0 0 0 0 -0 0</pose>
        <geometry>
          <mesh>
            <scale>1 1 1</scale>
            <uri>file:///home/adil/sim_ws/src/six_dof/meshes/link5.stl</uri>
          </mesh>
        </geometry>
        <surface>
          <contact>
            <ode/>
          </contact>
          <friction>
            <ode>
              <mu>5</mu>
              <mu2>5</mu2>
            </ode>
          </friction>
        </surface>
      </collision>
      <visual name='link5_visual'>
        <pose frame=''>0 0 0 0 -0 0</pose>
        <geometry>
          <mesh>
            <scale>1 1 1</scale>
            <uri>file:///home/adil/sim_ws/src/six_dof/meshes/link5.stl</uri>
          </mesh>
        </geometry>
        <material>
          <script>
            <name>Gazebo/Grey</name>
            <uri>file://media/materials/scripts/gazebo.material</uri>
          </script>
        </material>
      </visual>
      <gravity>1</gravity>
      <velocity_decay/>
    </link>
    <joint name='link4_link5_joint' type='revolute'>
      <child>link5</child>
      <parent>link4</parent>
      <axis>
        <xyz>0 1 4e-06</xyz>
        <limit>
          <lower>-3</lower>
          <upper>3</upper>
          <effort>200</effort>
          <velocity>3</velocity>
        </limit>
        <dynamics>
          <spring_reference>0</spring_reference>
          <spring_stiffness>0</spring_stiffness>
        </dynamics>
        <use_parent_model_frame>1</use_parent_model_frame>
      </axis>
    </joint>
    <link name='finger1'>
      <pose frame=''>-0.149999 2.488 0.823001 3.14159 -7e-06 -3.14159</pose>
      <inertial>
        <pose frame=''>0 0.074249 -0.033 0 -0 0</pose>
        <mass>1</mass>
        <inertia>
          <ixx>0.00249633</ixx>
          <ixy>0</ixy>
          <ixz>-0</ixz>
          <iyy>0.00249633</iyy>
          <iyz>-0</iyz>
          <izz>0.00343542</izz>
        </inertia>
      </inertial>
      <collision name='finger1_collision'>
        <pose frame=''>0 0 0 0 -0 0</pose>
        <geometry>
          <mesh>
            <scale>1 1 1</scale>
            <uri>file:///home/adil/sim_ws/src/six_dof/meshes/fin1.stl</uri>
          </mesh>
        </geometry>
        <surface>
          <contact>
            <ode>
              <kp>1e+06</kp>
              <kd>1</kd>
              <min_depth>0.001</min_depth>
            </ode>
          </contact>
          <friction>
            <ode>
              <mu>1000</mu>
              <mu2>1000</mu2>
            </ode>
          </friction>
        </surface>
      </collision>
      <visual name='finger1_visual'>
        <pose frame=''>0 0 0 0 -0 0</pose>
        <geometry>
          <mesh>
            <scale>1 1 1</scale>
            <uri>file:///home/adil/sim_ws/src/six_dof/meshes/fin1.stl</uri>
          </mesh>
        </geometry>
        <material>
          <script>
            <uri>__default__</uri>
            <name>__default__</name>
          </script>
        </material>
      </visual>
      <gravity>1</gravity>
      <velocity_decay/>
    </link>
    <joint name='l_finger_joint' type='prismatic'>
      <child>finger1</child>
      <parent>link5</parent>
      <axis>
        <xyz>-1 -0 7e-06</xyz>
        <limit>
          <lower>0</lower>
          <upper>0.1</upper>
          <effort>60</effort>
          <velocity>0.05</velocity>
        </limit>
        <dynamics>
          <damping>100</damping>
          <friction>0</friction>
          <spring_reference>0</spring_reference>
          <spring_stiffness>0</spring_stiffness>
        </dynamics>
        <use_parent_model_frame>1</use_parent_model_frame>
      </axis>
    </joint>
    <link name='finger2'>
      <pose frame=''>0.010001 2.488 0.823 3.14159 -7e-06 -3.14159</pose>
      <inertial>
        <pose frame=''>0 0.074249 -0.033 0 -0 0</pose>
        <mass>1</mass>
        <inertia>
          <ixx>0.00249633</ixx>
          <ixy>0</ixy>
          <ixz>-0</ixz>
          <iyy>0.00249633</iyy>
          <iyz>-0</iyz>
          <izz>0.00343542</izz>
        </inertia>
      </inertial>
      <collision name='finger2_collision'>
        <pose frame=''>0 0 0 0 -0 0</pose>
        <geometry>
          <mesh>
            <scale>1 1 1</scale>
            <uri>file:///home/adil/sim_ws/src/six_dof/meshes/fin2.stl</uri>
          </mesh>
        </geometry>
        <surface>
          <contact>
            <ode>
              <kp>1e+06</kp>
              <kd>1</kd>
              <min_depth>0.001</min_depth>
            </ode>
          </contact>
          <friction>
            <ode>
              <mu>1000</mu>
              <mu2>1000</mu2>
            </ode>
          </friction>
        </surface>
      </collision>
      <visual name='finger2_visual'>
        <pose frame=''>0 0 0 0 -0 0</pose>
        <geometry>
          <mesh>
            <scale>1 1 1</scale>
            <uri>file:///home/adil/sim_ws/src/six_dof/meshes/fin2.stl</uri>
          </mesh>
        </geometry>
        <material>
          <script>
            <uri>__default__</uri>
            <name>__default__</name>
          </script>
        </material>
      </visual>
      <gravity>1</gravity>
      <velocity_decay/>
    </link>
    <joint name='r_finger_joint' type='prismatic'>
      <child>finger2</child>
      <parent>link5</parent>
      <axis>
        <xyz>1 0 -7e-06</xyz>
        <limit>
          <lower>0</lower>
          <upper>0.1</upper>
          <effort>60</effort>
          <velocity>0.05</velocity>
        </limit>
        <dynamics>
          <damping>100</damping>
          <friction>0</friction>
          <spring_reference>0</spring_reference>
          <spring_stiffness>0</spring_stiffness>
        </dynamics>
        <use_parent_model_frame>1</use_parent_model_frame>
      </axis>
    </joint>
    <plugin name='gazebo_grasp_fix' filename='libgazebo_grasp_fix.so'>
      <arm>
        <arm_name>robot</arm_name>
        <palm_link>link5</palm_link>
        <gripper_link>finger1</gripper_link>
        <gripper_link>finger2</gripper_link>
      </arm>
      <forces_angle_tolerance>50</forces_angle_tolerance>
      <update_rate>4</update_rate>
      <grip_count_threshold>4</grip_count_threshold>
      <max_grip_count>8</max_grip_count>
      <release_tolerance>0.002</release_tolerance>
      <disable_collisions_on_attach>1</disable_collisions_on_attach>
      <contact_topic>__default_topic__</contact_topic>
    </plugin>
    <static>0</static>
    <plugin name='gazebo_ros_control' filename='libgazebo_ros_control.so'>
      <robotNamespace>/robot</robotNamespace>
      <robotSimType>gazebo_ros_control/DefaultRobotHWSim</robotSimType>
      <legacyModeNS>1</legacyModeNS>
    </plugin>
  </model>
</sdf>
